<mujoco model="rizon4sgripper">
  <compiler angle="radian" meshdir="../objects"/>

  <option integrator="implicitfast"/>

  <option cone="elliptic" impratio="10"/>

  <default>
    <default class="rizon4sgripper">
      <joint armature="0.1" damping="1"/>
      <position inheritrange="1"/>
      <default class="visual">
        <geom type="mesh" group="2" contype="0" conaffinity="0"/>
      </default>
      <default class="collision">
        <geom type="mesh" group="3" mass="0" density="0"/>
      </default>
      <site size="0.001" rgba="0.5 0.5 0.5 0.3" group="4"/>
    </default>

    <default class="2f85">
      <mesh scale="0.001 0.001 0.001"/>
      <general biastype="affine"/>

      <joint axis="0 0 1"/>
      <default class="driver">
        <joint range="0 0.9" armature="0.005" damping="0.1" solimplimit="0.95 0.99 0.001" solreflimit="0.005 1"/>
      </default>
      <default class="follower">
        <joint range="-0.872664 0.9" armature="0.001"  solimplimit="0.95 0.99 0.001" solreflimit="0.005 1"/>
      </default>
      <default class="spring_link">
        <joint range="-0.29670597283 0.9" armature="0.001" stiffness="0.05" springref="2.62" damping="0.00125"/>
      </default>
      <default class="coupler">
        <joint range="-1.57 0" armature="0.001" solimplimit="0.95 0.99 0.001" solreflimit="0.005 1"/>
      </default>

      <default class="visual-2f85">
        <geom type="mesh" contype="0" conaffinity="0" group="2" material="black"/>
      </default>
      <default class="collision-2f85">
        <geom type="mesh" group="3"/>
        <default class="pad_box1">
          <geom mass="1e-6" type="box" pos="0.043258  0 0.12"  size="0.002 0.011 0.009375" friction="0.7"
            solimp="0.95 0.99 0.001" solref="0.004 1" priority="1" rgba="0.55 0.55 0.55 1"/>
        </default>
        <default class="pad_box2">
          <geom mass="1e-6" type="box" pos="0.043258 0 0.13875" size="0.002 0.011 0.009375" friction="0.6"
            solimp="0.95 0.99 0.001" solref="0.004 1" priority="1" rgba="0.45 0.45 0.45 1"/>
        </default>
      </default>
    </default>
  </default>

  <asset>
    <mesh name="link0" file="./rizon4s/link0.stl"/>
    <mesh name="link1" file="./rizon4s/link1.stl"/>
    <mesh name="link2" file="./rizon4s/link2.stl"/>
    <mesh name="link3" file="./rizon4s/link3.stl"/>
    <mesh name="link4" file="./rizon4s/link4.stl"/>
    <mesh name="link5" file="./rizon4s/link5.stl"/>
    <mesh name="link6" file="./rizon4s/link6.stl"/>
    <mesh name="link7" file="./rizon4s/link7.stl"/>

    <material name="metal" rgba="0.58 0.58 0.58 1"/>
    <material name="silicone" rgba="0.1882 0.1882 0.1882 1"/>
    <material name="black" rgba="0.149 0.149 0.149 1"/>

    <mesh file="./robotiq-2f85/base.stl"/>
    <mesh file="./robotiq-2f85/base_coupling.stl"/>
    <mesh file="./robotiq-2f85/c-a01-85-open.stl"/>
    <mesh file="./robotiq-2f85/driver.stl"/>
    <mesh file="./robotiq-2f85/coupler.stl"/>
    <mesh file="./robotiq-2f85/spring_link.stl"/>
    <mesh file="./robotiq-2f85/follower.stl"/>
    <mesh file="./robotiq-2f85/tongue.stl"/>
  </asset>

  <!-- Everything merged uptil this point -->

  <worldbody>
    <geom name="hull" type="mesh" rgba="0.7 0.7 0.7 1" mesh="link0"/>
    <body name="link1" pos="0 0 0.155" quat="0 0 0 -1">
      <inertial pos="0 0.01 0.15" mass="3.7" diaginertia="0.03 0.03 0.01"/>
      <joint name="joint1" pos="0 0 0" axis="0 0 1" range="-2.7925 2.7925" actuatorfrcrange="-123 123"/>
      <geom type="mesh" rgba="1 1 1 1" mesh="link1"/>
      <body name="link2" pos="0 0.03 0.21">
        <inertial pos="0 0.04 0.1" mass="2.7" diaginertia="0.02 0.02 0.01"/>
        <joint name="joint2" pos="0 0 0" axis="0 1 0" range="-2.2689 2.2689" actuatorfrcrange="-123 123"/>
        <geom type="mesh" rgba="1 1 1 1" mesh="link2"/>
        <body name="link3" pos="0 0.035 0.205">
          <inertial pos="-0.01 0 0.13" mass="2.4" diaginertia="0.01 0.01 0.01"/>
          <joint name="joint3" pos="0 0 0" axis="0 0 1" range="-2.9671 2.9671" actuatorfrcrange="-64 64"/>
          <geom type="mesh" rgba="1 1 1 1" mesh="link3"/>
          <body name="link4" pos="-0.02 -0.03 0.19" quat="0 0 0 -1">
            <inertial pos="-0.01 0.03 0.1" mass="2.4" diaginertia="0.02 0.02 0.01"/>
            <joint name="joint4" pos="0 0 0" axis="0 1 0" range="-1.8675 2.6878" actuatorfrcrange="-64 64"/>
            <geom type="mesh" rgba="1 1 1 1" mesh="link4"/>
            <body name="link5" pos="-0.02 0.025 0.195" quat="0 0 0 -1">
              <inertial pos="0 0 0.13" mass="2.4" diaginertia="0.01 0.01 0.01"/>
              <joint name="joint5" pos="0 0 0" axis="0 0 1" range="-2.9671 2.9671" actuatorfrcrange="-39 39"/>
              <geom type="mesh" rgba="1 1 1 1" mesh="link5"/>
              <body name="link6" pos="0 0.03 0.19">
                <inertial pos="0.02 0.06 0.07" mass="2.2" diaginertia="0.01 0.01 0.01"/>
                <joint name="joint6" pos="0 0 0" axis="0 1 0" range="-1.3963 4.5379" actuatorfrcrange="-39 39"/>
                <geom type="mesh" rgba="1 1 1 1" mesh="link6"/>
                <body name="link7" pos="-0.015 0.073 0.11" quat="0.707107 0 -0.707107 0">
                  <inertial pos="0 0 0.05" mass="1.4" diaginertia="0.1 0.1 0.1"/>
                  <joint name="joint7" pos="0 0 0" axis="0 0 1" range="-2.9671 2.9671" actuatorfrcrange="-39 39"/>
                  <geom type="mesh" rgba="1 1 1 1" mesh="link7"/>
                  <body name="base" childclass="2f85" pos="0 0 0.124">
                    <inertial mass="0.777441" pos="0 -2.70394e-05 0.0354675" quat="1 -0.00152849 0 0"
                      diaginertia="0.000260285 0.000225381 0.000152708"/>
                    <geom class="visual" pos="0 0 0.0108" quat="0 0 0 1"   mesh="base"/>
                    <geom class="visual" pos="0 0 0.004" quat="1 -1 0 0"   mesh="base_coupling"/>
                    <geom class="visual" pos="0 0 0.0108" quat="1 0 0 0"  material="metal" mesh="c-a01-85-open"/>
                    <geom class="collision" mesh="base"/>
                    <!-- Left-hand side 4-bar linkage -->
                    <body name="left_driver" pos="-0.0306011 0.00475 0.0657045" quat="1 -1 0 0">
                      <inertial mass="0.00899563" pos="0 0.0177547 0.00107314" quat="0.681301 0.732003 0 0"
                          diaginertia="1.72352e-06 1.60906e-06 3.22006e-07"/>
                      <joint name="left_driver_joint" class="driver"/>
                      <geom class="visual" pos="0.0306011 0.0549045 -0.0047" quat="1 1 0 0"  material="metal" mesh="driver"/>
                      <geom class="collision" pos="0.0306011 0.0549045 -0.0047" quat="1 1 0 0"   mesh="driver"/>
                      <body name="left_coupler" pos="-0.0314249 0.00453223 -0.0102" quat="0 0 0 1">
                        <inertial mass="0.0140974" pos="0 0.00301209 0.0232175" quat="0.705636 -0.0455904 0.0455904 0.705636"
                        diaginertia="4.16206e-06 3.52216e-06 8.88131e-07"/>
                        <geom class="visual" pos="-0.062026 -0.0503723 0.0055" quat="1 -1 0 0"   mesh="coupler"/>
                        <geom class="collision" pos="-0.062026 -0.0503723 0.0055" quat="1 -1 0 0"  mesh="coupler"/>
                      </body>
                    </body>
                    <body name="left_spring_link" pos="-0.0127 -0.012 0.07222" quat="1 -1 0 0">
                      <inertial mass="0.0221642" pos="-8.65005e-09 0.0181624 0.0212658" quat="0.663403 -0.244737 0.244737 0.663403"
                          diaginertia="8.96853e-06 6.71733e-06 2.63931e-06"/>
                      <joint name="left_spring_link_joint" class="spring_link"/>
                      <geom class="visual" pos="0.0127 0.06142 0.01205" quat="1 1 0 0" type="mesh"  mesh="spring_link"/>
                      <geom class="collision" pos="0.0127 0.06142 0.01205" quat="1 1 0 0" type="mesh"  mesh="spring_link"/>
                      <body name="left_follower" pos="-0.0382079 -0.0425003 0.00295" quat="0 -1 -1.90231e-05 0">
                        <inertial mass="0.0125222" pos="0 -0.011046 0.0124786" quat="1 0.1664 0 0"
                        diaginertia="2.67415e-06 2.4559e-06 6.02031e-07"/>
                        <joint name="left_follower" class="follower"/>
                        <geom class="visual" pos="0.0509079 -0.10392 -0.0091" quat="1 -1 0 0" type="mesh"  mesh="follower"/>
                        <geom class="visual" pos="0.0509079 -0.10392 -0.0091" quat="1 -1 0 0" type="mesh" material="metal" mesh="tongue"/>
                        <geom class="collision" pos="0.0509079 -0.10392 -0.0091" quat="1 -1 0 0" type="mesh"  mesh="follower"/>
                        <geom class="collision" pos="0.0509079 -0.10392 -0.0091" quat="1 -1 0 0" type="mesh"  mesh="tongue"/>
                        <body name="left_pad" pos="-0.0377897 -0.103916 -0.0091" quat="1 -1 0 0" >
                          <geom class="pad_box1" name="left_pad1"/>
                          <geom class="pad_box2" name="left_pad2"/>
                        </body>
                      </body>
                    </body>
                    <!-- Right-hand side 4-bar linkage -->
                    <body name="right_driver" pos="0.0306011 -0.00475 0.0657045" quat="0 0 -1 1">
                      <inertial mass="0.00899563" pos="2.96931e-12 0.0177547 0.00107314" quat="0.681301 0.732003 0 0"
                      diaginertia="1.72352e-06 1.60906e-06 3.22006e-07"/>
                      <joint name="right_driver_joint" class="driver"/>
                      <geom class="visual" pos="0.0306011 0.0549045 -0.0047" quat="1 1 0 0" material="metal" mesh="driver"/>
                      <geom class="collision" pos="0.0306011 0.0549045 -0.0047" quat="1 1 0 0"  mesh="driver"/>
                      <body name="right_coupler" pos="-0.0314249 0.00453223 -0.0102" quat="0 0 0 1">
                        <inertial mass="0.0140974" pos="0 0.00301209 0.0232175" quat="0.705636 -0.0455904 0.0455904 0.705636"
                        diaginertia="4.16206e-06 3.52216e-06 8.88131e-07"/>
                        <geom class="visual" pos="-0.062026 -0.0503723 0.0055" quat="1 -1 0 0"   mesh="coupler"/>
                        <geom class="collision" pos="-0.062026 -0.0503723 0.0055" quat="1 -1 0 0"   mesh="coupler"/>
                      </body>
                    </body>
                    <body name="right_spring_link" pos="0.0127 0.012 0.07222" quat="0 0 -1 1">
                      <inertial mass="0.0221642" pos="-8.65005e-09 0.0181624 0.0212658" quat="0.663403 -0.244737 0.244737 0.663403"
                      diaginertia="8.96853e-06 6.71733e-06 2.63931e-06"/>
                      <joint name="right_spring_link_joint" class="spring_link"/>
                      <geom class="visual" pos="0.0127 0.06142 0.01205" quat="1 1 0 0"   mesh="spring_link"/>
                      <geom class="collision" pos="0.0127 0.06142 0.01205" quat="1 1 0 0"   mesh="spring_link"/>
                      <body name="right_follower" pos="-0.0382079 -0.0425003 0.00295" quat="0 -1 0 0">
                        <inertial mass="0.0125222" pos="0 -0.011046 0.0124786" quat="1 0.1664 0 0"
                        diaginertia="2.67415e-06 2.4559e-06 6.02031e-07"/>
                        <joint name="right_follower_joint" class="follower"/>
                        <geom class="visual" pos="0.0509079 -0.10392 -0.0091" quat="1 -1 0 0"  material="metal" mesh="tongue"/>
                        <geom class="visual" pos="0.0509079 -0.10392 -0.0091" quat="1 -1 0 0"   mesh="follower"/>
                        <geom class="collision" pos="0.0509079 -0.10392 -0.0091" quat="1 -1 0 0"   mesh="tongue"/>
                        <geom class="collision" pos="0.0509079 -0.10392 -0.0091" quat="1 -1 0 0"   mesh="follower"/>
                        <body name="right_pad" pos="-0.0377897 -0.103916 -0.0091"   quat="1 -1 0 0" >
                          <geom class="pad_box1" name="right_pad1"/>
                          <geom class="pad_box2" name="right_pad2"/>
                        </body>
                      </body>
                    </body>
                  </body>
                </body>
              </body>
            </body>
          </body>
        </body>
      </body>
    </body>
  </worldbody>

  <contact>
    <exclude body1="base" body2="left_driver"/>
    <exclude body1="base" body2="right_driver"/>
    <exclude body1="base" body2="left_spring_link"/>
    <exclude body1="base" body2="right_spring_link"/>
    <exclude body1="right_coupler" body2="right_follower"/>
    <exclude body1="left_coupler" body2="left_follower"/>
  </contact>

  <tendon>
    <fixed name="split">
      <joint joint="right_driver_joint" coef="0.485"/>
      <joint joint="left_driver_joint" coef="0.485"/>
    </fixed>
  </tendon>

  <equality>
    <connect anchor="-0.0179014 -0.00651468 0.0044" body1="right_follower" body2="right_coupler" solimp="0.95 0.99 0.001" solref="0.005 1"/>
    <connect anchor="-0.0179014 -0.00651468 0.0044" body1="left_follower" body2="left_coupler" solimp="0.95 0.99 0.001" solref="0.005 1"/>
    <joint joint1="right_driver_joint" joint2="left_driver_joint" polycoef="0 1 0 0 0" solimp="0.95 0.99 0.001"
    solref="0.005 1"/>
  </equality>

  <actuator>
    <motor class="rizon4sgripper" name="joint1" joint="joint1" ctrlrange="-87 87"/>
    <motor class="rizon4sgripper" name="joint2" joint="joint2" ctrlrange="-87 87"/>
    <motor class="rizon4sgripper" name="joint3" joint="joint3" ctrlrange="-87 87"/>
    <motor class="rizon4sgripper" name="joint4" joint="joint4" ctrlrange="-87 87"/>
    <motor class="rizon4sgripper" name="joint5" joint="joint5" ctrlrange="-12 12"/>
    <motor class="rizon4sgripper" name="joint6" joint="joint6" ctrlrange="-12 12"/>
    <motor class="rizon4sgripper" name="joint7" joint="joint7" ctrlrange="-12 12"/>
    <general class="2f85" name="fingers_actuator" tendon="split" forcerange="-5 5" ctrlrange="0 255"
      gainprm="0.3137255 0 0" biasprm="0 -100 -10"/>
  </actuator>

  <keyframe>
    <key name="home" qpos="0 0 0 -1.57079 0 1.57079 -0.7853 0 0 0 0 0 0" ctrl="0 0 0 -1.57079 0 1.57079 -0.7853 0"/>
  </keyframe>

</mujoco>
