<?xml version="1.0"?>
<!-- ======================================================================== -->
<!-- | Flexiv Rizon 4s (with blurred dynamic parameters)                    | -->
<!-- ======================================================================== -->
<robot name="rizon4s">
    <joint name="joint1" type="revolute">
        <parent link="base_link"/>
        <child link="link1"/>
        <origin rpy="0.0 0.0 -3.141592653589793" xyz="0.0 0.0 0.155"/>
        <axis xyz="0 0 1"/>
        <limit effort="123" lower="-2.7925" upper="2.7925" velocity="2.0944"/>
    </joint> 
    <joint name="joint2" type="revolute">
        <parent link="link1"/>
        <child link="link2"/>
        <origin rpy="0.0 0.0 0.0" xyz="0.0 0.03 0.21"/>
        <axis xyz="0 1 0"/>
        <limit effort="123" lower="-2.2689" upper="2.2689" velocity="2.0944"/>
    </joint>
    <joint name="joint3" type="revolute">
        <parent link="link2"/>
        <child link="link3"/>
        <origin rpy="0.0 0.0 0.0" xyz="0.0 0.035 0.205"/>
        <axis xyz="0 0 1"/>
        <limit effort="64" lower="-2.9671" upper="2.9671" velocity="2.4435"/>
    </joint>
    <joint name="joint4" type="revolute">
        <parent link="link3"/>
        <child link="link4"/>
        <origin rpy="0.0 0.0 -3.141592653589793" xyz="-0.02 -0.03 0.19"/>
        <axis xyz="0 1 0"/>
        <limit effort="64" lower="-1.8675" upper="2.6878" velocity="2.4435"/>
    </joint>
    <joint name="joint5" type="revolute">
        <parent link="link4"/>
        <child link="link5"/>
        <origin rpy="0.0 0.0 -3.141592653589793" xyz="-0.02 0.025 0.195"/>
        <axis xyz="0 0 1"/>
        <limit effort="39" lower="-2.9671" upper="2.9671" velocity="4.8869"/>
    </joint>
    <joint name="joint6" type="revolute">
        <parent link="link5"/>
        <child link="link6"/>
        <origin rpy="0.0 0.0 0.0" xyz="0.0 0.03 0.19"/>
        <axis xyz="0 1 0"/>
        <limit effort="39" lower="-1.3963" upper="4.5379" velocity="4.8869"/>
    </joint>
    <joint name="joint7" type="revolute">
        <parent link="link6"/>
        <child link="link7"/>
        <origin rpy="0.0 -1.5707963478683205 0.0" xyz="-0.015 0.073 0.11"/>
        <axis xyz="0 0 1"/>
        <limit effort="39" lower="-2.9671" upper="2.9671" velocity="4.8869"/>
    </joint>
    <joint name="link7_to_flange" type="fixed">
        <parent link="link7"/>
        <child link="flange"/>
        <origin rpy="0.0 0.0 -3.141592653589793" xyz="0.0 0.0 0.124"/>
    </joint>
    <joint name="link7_to_robotiq" type="fixed">
        <parent link="link7"/>
        <child link="robotiq_arg2f_base_link"/>
        <origin rpy="0.0 0.0 0" xyz="0.0 0.0 0.124"/>
    </joint>
    <joint name="finger_joint" type="revolute">
      <origin rpy="0 0 3.141592653589793" xyz="0 -0.0306011 0.054904"/>
      <parent link="robotiq_arg2f_base_link"/>
      <child link="left_outer_knuckle"/>
      <axis xyz="1 0 0"/>
      <limit effort="1000" lower="0" upper="0.8" velocity="2.0"/>
    </joint>
    <joint name="left_outer_finger_joint" type="fixed">
      <origin rpy="0 0 0" xyz="0 0.0315 -0.0041"/>
      <parent link="left_outer_knuckle"/>
      <child link="left_outer_finger"/>
      <axis xyz="1 0 0"/>
    </joint>
    <joint name="left_inner_knuckle_joint" type="revolute">
      <!-- <origin xyz="0 ${reflect * -0.0127} 0.06142" rpy="${pi / 2 + .725} 0 ${(reflect - 1) * pi / 2}" /> -->
      <origin rpy="0 0 3.141592653589793" xyz="0 -0.0127 0.06142"/>
      <parent link="robotiq_arg2f_base_link"/>
      <child link="left_inner_knuckle"/>
      <axis xyz="1 0 0"/>
      <limit effort="1000" lower="0" upper="0.8757" velocity="2.0"/>
      <mimic joint="finger_joint" multiplier="1" offset="0"/>
    </joint>
    <joint name="left_inner_finger_joint" type="revolute">
      <origin rpy="0 0 0" xyz="0 0.0061 0.0471"/>
      <parent link="left_outer_finger"/>
      <child link="left_inner_finger"/>
      <axis xyz="1 0 0"/>
      <limit effort="1000" lower="0" upper="0.8757" velocity="2.0"/>
      <mimic joint="finger_joint" multiplier="-1" offset="0"/>
    </joint>
    <joint name="left_inner_finger_pad_joint" type="fixed">
      <origin rpy="0 0 0" xyz="0 -0.0220203446692936 0.03242"/>
      <parent link="left_inner_finger"/>
      <child link="left_inner_finger_pad"/>
      <axis xyz="0 0 1"/>
    </joint>
    <joint name="right_outer_knuckle_joint" type="revolute">
      <origin rpy="0 0 0" xyz="0 0.0306011 0.054904"/>
      <parent link="robotiq_arg2f_base_link"/>
      <child link="right_outer_knuckle"/>
      <axis xyz="1 0 0"/>
      <limit effort="1000" lower="0" upper="0.81" velocity="2.0"/>
      <mimic joint="finger_joint" multiplier="1" offset="0"/>
    </joint>
    <joint name="right_outer_finger_joint" type="fixed">
      <origin rpy="0 0 0" xyz="0 0.0315 -0.0041"/>
      <parent link="right_outer_knuckle"/>
      <child link="right_outer_finger"/>
      <axis xyz="1 0 0"/>
    </joint>
    <joint name="right_inner_knuckle_joint" type="revolute">
      <!-- <origin xyz="0 ${reflect * -0.0127} 0.06142" rpy="${pi / 2 + .725} 0 ${(reflect - 1) * pi / 2}" /> -->
      <origin rpy="0 0 0.0" xyz="0 0.0127 0.06142"/>
      <parent link="robotiq_arg2f_base_link"/>
      <child link="right_inner_knuckle"/>
      <axis xyz="1 0 0"/>
      <limit effort="1000" lower="0" upper="0.8757" velocity="2.0"/>
      <mimic joint="finger_joint" multiplier="1" offset="0"/>
    </joint>
    <joint name="right_inner_finger_joint" type="revolute">
      <origin rpy="0 0 0" xyz="0 0.0061 0.0471"/>
      <parent link="right_outer_finger"/>
      <child link="right_inner_finger"/>
      <axis xyz="1 0 0"/>
      <limit effort="1000" lower="0" upper="0.8757" velocity="2.0"/>
      <mimic joint="finger_joint" multiplier="-1" offset="0"/>
    </joint>
    <joint name="right_inner_finger_pad_joint" type="fixed">
      <origin rpy="0 0 0" xyz="0 -0.0220203446692936 0.03242"/>
      <parent link="right_inner_finger"/>
      <child link="right_inner_finger_pad"/>
      <axis xyz="0 0 1"/>
    </joint>
    <transmission name="finger_joint_trans">
      <type>transmission_interface/SimpleTransmission</type>
      <joint name="finger_joint">
        <hardwareInterface>PositionJointInterface</hardwareInterface>
      </joint>
      <actuator name="finger_joint_motor">
        <mechanicalReduction>1</mechanicalReduction>
      </actuator>
    </transmission>

    <link name="base_link">
        <inertial>
            <mass value="3.7"/>
            <origin rpy="0 0 0" xyz="0.0 -0.0 0.09"/>
            <inertia ixx="0.02" ixy="0.0" ixz="0.0" iyy="0.02" iyz="0.0" izz="0.01"/>
        </inertial>
        <visual name="shell">
            <origin rpy="0 0 0" xyz="0 0 0"/>
            <geometry>
                <mesh filename="package://meshes/rizon4s/visual/link0.obj"/>
            </geometry>
            <material name="rizon_light_grey"/>
        </visual>
        <collision name="hull">
            <origin rpy="0 0 0" xyz="0 0 0"/>
            <geometry>
                <mesh filename="package://meshes/rizon4s/collision/link0.stl"/>
            </geometry>
        </collision>
    </link>
    <link name="link1">
        <inertial>
            <mass value="3.7"/>
            <origin rpy="0 0 0" xyz="0.0 0.01 0.15"/>
            <inertia ixx="0.03" ixy="0.0" ixz="0.0" iyy="0.03" iyz="0.0" izz="0.01"/>
        </inertial>
        <visual name="shell">
            <origin rpy="0 0 0" xyz="0 0 0"/>
            <geometry>
                <mesh filename="package://meshes/rizon4s/visual/link1.obj"/>
            </geometry>
            <material name="rizon_light_grey"/>
        </visual>
        <visual name="ring">
            <origin rpy="0 0 0" xyz="0 0 -0.0025"/>
            <geometry>
                <mesh filename="package://meshes/rizon4s/visual/ring.obj" scale="0.062 0.062 0.002"/>
            </geometry>
            <material name="rizon_white"/>
        </visual>
        <collision name="hull">
            <origin rpy="0 0 0" xyz="0 0 0"/>
            <geometry>
                <mesh filename="package://meshes/rizon4s/collision/link1.stl"/>
            </geometry>
        </collision>
    </link>
    <link name="link2">
        <inertial>
            <mass value="2.7"/>
            <origin rpy="0 0 0" xyz="0.0 0.04 0.1"/>
            <inertia ixx="0.02" ixy="0.0" ixz="0.0" iyy="0.02" iyz="-0.0" izz="0.01"/>
        </inertial>
        <visual name="shell">
            <origin rpy="0 0 0" xyz="0 0 0"/>
            <geometry>
                <mesh filename="package://meshes/rizon4s/visual/link2.obj"/>
            </geometry>
            <material name="rizon_light_grey"/>
        </visual>
        <visual name="ring">
            <origin rpy="1.5707963 0 0" xyz="0 -0.0025 0"/>
            <geometry>
                <mesh filename="package://meshes/rizon4s/visual/ring.obj" scale="0.062 0.062 0.002"/>
            </geometry>
            <material name="rizon_white"/>
        </visual>
        <collision name="hull">
            <origin rpy="0 0 0" xyz="0 0 0"/>
            <geometry>
                <mesh filename="package://meshes/rizon4s/collision/link2.stl"/>
            </geometry>
        </collision>
    </link>
    <link name="link3">
        <inertial>
            <mass value="2.4"/>
            <origin rpy="0 0 0" xyz="-0.01 -0.0 0.13"/>
            <inertia ixx="0.01" ixy="0.0" ixz="-0.0" iyy="0.01" iyz="-0.0" izz="0.01"/>
        </inertial>
        <visual name="shell">
            <origin rpy="0 0 0" xyz="0 0 0"/>
            <geometry>
                <mesh filename="package://meshes/rizon4s/visual/link3.obj"/>
            </geometry>
            <material name="rizon_light_grey"/>
        </visual>
        <visual name="ring">
            <origin rpy="0 0 0" xyz="0 0 -0.0025"/>
            <geometry>
                <mesh filename="package://meshes/rizon4s/visual/ring.obj" scale="0.051 0.051 0.002"/>
            </geometry>
            <material name="rizon_white"/>
        </visual>
        <collision name="hull">
            <origin rpy="0 0 0" xyz="0 0 0"/>
            <geometry>
                <mesh filename="package://meshes/rizon4s/collision/link3.stl"/>
            </geometry>
        </collision>
    </link>
    <link name="link4">
        <inertial>
            <mass value="2.4"/>
            <origin rpy="0 0 0" xyz="-0.01 0.03 0.1"/>
            <inertia ixx="0.02" ixy="0.0" ixz="-0.0" iyy="0.02" iyz="-0.0" izz="0.01"/>
        </inertial>
        <visual name="shell">
            <origin rpy="0 0 0" xyz="0 0 0"/>
            <geometry>
                <mesh filename="package://meshes/rizon4s/visual/link4.obj"/>
            </geometry>
            <material name="rizon_light_grey"/>
        </visual>
        <visual name="ring">
            <origin rpy="1.5707963 0 0" xyz="0 -0.0025 0"/>
            <geometry>
                <mesh filename="package://meshes/rizon4s/visual/ring.obj" scale="0.051 0.051 0.002"/>
            </geometry>
            <material name="rizon_white"/>
        </visual>
        <collision name="hull">
            <origin rpy="0 0 0" xyz="0 0 0"/>
            <geometry>
                <mesh filename="package://meshes/rizon4s/collision/link4.stl"/>
            </geometry>
        </collision>
    </link>
    <link name="link5">
        <inertial>
            <mass value="2.4"/>
            <origin rpy="0 0 0" xyz="-0.0 0.0 0.13"/>
            <inertia ixx="0.01" ixy="0.0" ixz="0.0" iyy="0.01" iyz="0.0" izz="0.01"/>
        </inertial>
        <visual name="shell">
            <origin rpy="0 0 0" xyz="0 0 0"/>
            <geometry>
                <mesh filename="package://meshes/rizon4s/visual/link5.obj"/>
            </geometry>
            <material name="rizon_light_grey"/>
        </visual>
        <visual name="ring">
            <origin rpy="0 0 0" xyz="0 0 -0.0025"/>
            <geometry>
                <mesh filename="package://meshes/rizon4s/visual/ring.obj" scale="0.051 0.051 0.002"/>
            </geometry>
            <material name="rizon_white"/>
        </visual>
        <collision name="hull">
            <origin rpy="0 0 0" xyz="0 0 0"/>
            <geometry>
                <mesh filename="package://meshes/rizon4s/collision/link5.stl"/>
            </geometry>
        </collision>
    </link>
    <link name="link6">
        <inertial>
            <mass value="2.2"/>
            <origin rpy="0 0 0" xyz="0.02 0.06 0.07"/>
            <inertia ixx="0.01" ixy="0.0" ixz="0.0" iyy="0.01" iyz="0.0" izz="0.01"/>
        </inertial>
        <visual name="shell">
            <origin rpy="0 0 0" xyz="0 0 0"/>
            <geometry>
                <mesh filename="package://meshes/rizon4s/visual/link6.obj"/>
            </geometry>
            <material name="rizon_light_grey"/>
        </visual>
        <visual name="ring">
            <origin rpy="1.5707963 0 0" xyz="0 -0.0025 0"/>
            <geometry>
                <mesh filename="package://meshes/rizon4s/visual/ring.obj" scale="0.051 0.051 0.002"/>
            </geometry>
            <material name="rizon_white"/>
        </visual>
        <collision name="hull">
            <origin rpy="0 0 0" xyz="0 0 0"/>
            <geometry>
                <mesh filename="package://meshes/rizon4s/collision/link6.stl"/>
            </geometry>
        </collision>
    </link>
    <link name="link7">
        <inertial>
            <mass value="1.4"/>
            <origin rpy="0 0 0" xyz="0.0 0.0 0.05"/>
            <inertia ixx="0.1" ixy="0.0" ixz="0.0" iyy="0.1" iyz="0.0" izz="0.1"/>
        </inertial>
        <visual name="shell">
            <origin rpy="0 0 0" xyz="0 0 0"/>
            <geometry>
                <mesh filename="package://meshes/rizon4s/visual/link7.obj"/>
            </geometry>
            <material name="rizon_light_grey"/>
        </visual>
        <visual name="ring">
            <origin rpy="0 0 0" xyz="0 0 -0.0025"/>
            <geometry>
                <mesh filename="package://meshes/rizon4s/visual/ring.obj" scale="0.051 0.051 0.002"/>
            </geometry>
            <material name="rizon_white"/>
        </visual>
        <collision name="hull">
            <origin rpy="0 0 0" xyz="0 0 0"/>
            <geometry>
                <mesh filename="package://meshes/rizon4s/collision/link7.stl"/>
            </geometry>
        </collision>
    </link>
    <link name="flange"/>
    <material name="rizon_light_grey">
        <color rgba="0.7 0.7 0.7 1.0"/>
    </material>
    <material name="rizon_dark_grey">
        <color rgba="0.4 0.4 0.4 1.0"/>
    </material>
    <material name="rizon_white">
        <color rgba="1.0 1.0 1.0 1.0"/>
    </material>

    <link name="robotiq_arg2f_base_link">
      <inertial>
        <origin rpy="0 0 0" xyz="8.625E-08 -4.6583E-06 0.03145"/>
        <mass value="0.22652"/>
        <inertia ixx="0.00020005" ixy="-4.2442E-10" ixz="-2.9069E-10" iyy="0.00017832" iyz="-3.4402E-08" izz="0.00013478"/>
      </inertial>
    </link>
    <link name="left_outer_knuckle">
      <inertial>
          <origin xyz="-0.000200000000003065 0.0199435877845359 0.0292245259211331" rpy="0 0 0" />
          <mass value="0.00853198276973456" />
          <inertia ixx="2.89328108496468E-06" ixy="-1.57935047237397E-19" ixz="-1.93980378593255E-19" iyy="1.86719750325683E-06" iyz="-1.21858577871576E-06" izz="1.21905238907251E-06" />
          </inertial>
    </link>
    <link name="left_outer_finger">
      <inertial>
          <origin xyz="0.00030115855001899 0.0373907951953854 -0.0208027427000385" rpy="0 0 0" />
          <mass value="0.022614240507152" />
          <inertia ixx="1.52518312458174E-05" ixy="9.76583423954399E-10" ixz="-5.43838577022588E-10" iyy="6.17694243867776E-06" iyz="6.78636130740228E-06" izz="1.16494917907219E-05" />
          </inertial>
    </link>
    <link name="left_inner_finger">
      <inertial>
          <origin xyz="0.000299999999999317 0.0160078233491243 -0.0136945669206257" rpy="0 0 0" />
          <mass value="0.0104003125914103" />
          <inertia ixx="2.71909453810972E-06" ixy="1.35402465472579E-21" ixz="-7.1817349065269E-22" iyy="7.69100314106116E-07" iyz="6.74715432769696E-07" izz="2.30315190420171E-06" />
          </inertial>
    </link>
    <link name="left_inner_finger_pad">
    </link>
    <link name="left_inner_knuckle">
      <inertial>
          <origin xyz="0.000123011831763771 0.0507850843201817 0.00103968640075166" rpy="0 0 0" />
        <mass value="0.0271177346495152" />
          <inertia ixx="2.61910379223783E-05" ixy="-2.43616858946494E-07" ixz="-6.37789906117123E-09" iyy="2.8270243746167E-06" iyz="-5.37200748039765E-07" izz="2.83695868220296E-05" />
          </inertial>
    </link>
    <link name="right_outer_knuckle">
      <inertial>
          <origin xyz="-0.000200000000003065 0.0199435877845359 0.0292245259211331" rpy="0 0 0" />
          <mass value="0.00853198276973456" />
          <inertia ixx="2.89328108496468E-06" ixy="-1.57935047237397E-19" ixz="-1.93980378593255E-19" iyy="1.86719750325683E-06" iyz="-1.21858577871576E-06" izz="1.21905238907251E-06" />
          </inertial>
    </link>
    <link name="right_outer_finger">
      <inertial>
          <origin xyz="0.00030115855001899 0.0373907951953854 -0.0208027427000385" rpy="0 0 0" />
          <mass value="0.022614240507152" />
          <inertia ixx="1.52518312458174E-05" ixy="9.76583423954399E-10" ixz="-5.43838577022588E-10" iyy="6.17694243867776E-06" iyz="6.78636130740228E-06" izz="1.16494917907219E-05" />
          </inertial>
    </link>
    <link name="right_inner_finger">
      <inertial>
          <origin xyz="0.000299999999999317 0.0160078233491243 -0.0136945669206257" rpy="0 0 0" />
          <mass value="0.0104003125914103" />
          <inertia ixx="2.71909453810972E-06" ixy="1.35402465472579E-21" ixz="-7.1817349065269E-22" iyy="7.69100314106116E-07" iyz="6.74715432769696E-07" izz="2.30315190420171E-06" />
          </inertial>
    </link>
    <link name="right_inner_finger_pad">
    </link>
    <link name="right_inner_knuckle">
      <inertial>
          <origin xyz="0.000123011831763771 0.0507850843201817 0.00103968640075166" rpy="0 0 0" />
        <mass value="0.0271177346495152" />
          <inertia ixx="2.61910379223783E-05" ixy="-2.43616858946494E-07" ixz="-6.37789906117123E-09" iyy="2.8270243746167E-06" iyz="-5.37200748039765E-07" izz="2.83695868220296E-05" />
          </inertial>
    </link>
</robot>


  
  


