<mujoco model="rizon4s">
  <option integrator="implicitfast"/>
  <compiler angle="radian" meshdir="../objects"/>

  <default>
    <default class="rizon4s">
      <joint armature="0.1" damping="1"/>
      <position inheritrange="1"/>
      <default class="visual">
        <geom type="mesh" group="2" contype="0" conaffinity="0"/>
      </default>
      <default class="collision">
        <geom type="mesh" group="3" mass="0" density="0"/>
      </default>
      <site size="0.001" rgba="0.5 0.5 0.5 0.3" group="4"/>
    </default>
  </default>

  <asset>
    <mesh name="link0" file="./rizon4s/link0.stl"/>
    <mesh name="link1" file="./rizon4s/link1.stl"/>
    <mesh name="link2" file="./rizon4s/link2.stl"/>
    <mesh name="link3" file="./rizon4s/link3.stl"/>
    <mesh name="link4" file="./rizon4s/link4.stl"/>
    <mesh name="link5" file="./rizon4s/link5.stl"/>
    <mesh name="link6" file="./rizon4s/link6.stl"/>
    <mesh name="link7" file="./rizon4s/link7.stl"/>

    <material name="0.596078_0.666667_0.686275_0.000000_0.000000" specular="0.0" shininess="0.0" rgba="0.5961 0.6667 0.6863 1"/>
    <mesh file="./male-connector-minimal/male-connector-minimal/male-connector-minimal.obj"/>
    <mesh file="./male-connector-minimal/male-connector-minimal/male-connector-minimal_collision_0.obj"/>
    <mesh file="./male-connector-minimal/male-connector-minimal/male-connector-minimal_collision_1.obj"/>
    <mesh file="./male-connector-minimal/male-connector-minimal/male-connector-minimal_collision_2.obj"/>
    <mesh file="./male-connector-minimal/male-connector-minimal/male-connector-minimal_collision_3.obj"/>
    <mesh file="./male-connector-minimal/male-connector-minimal/male-connector-minimal_collision_4.obj"/>
    <mesh file="./male-connector-minimal/male-connector-minimal/male-connector-minimal_collision_5.obj"/>
    <mesh file="./male-connector-minimal/male-connector-minimal/male-connector-minimal_collision_6.obj"/>
    <mesh file="./male-connector-minimal/male-connector-minimal/male-connector-minimal_collision_7.obj"/>

    <material name="0.498039_0.498039_0.498039_0.000000_0.000000" specular="0.0" shininess="0.0" rgba="0.498 0.498 0.498 1"/>
    <mesh file="./female-connector-truncated/female-connector-truncated/female-connector-truncated.obj"/>
    <mesh file="./female-connector-truncated/female-connector-truncated/female-connector-truncated_collision_0.obj"/>
    <mesh file="./female-connector-truncated/female-connector-truncated/female-connector-truncated_collision_1.obj"/>
    <mesh file="./female-connector-truncated/female-connector-truncated/female-connector-truncated_collision_2.obj"/>
    <mesh file="./female-connector-truncated/female-connector-truncated/female-connector-truncated_collision_3.obj"/>
    <mesh file="./female-connector-truncated/female-connector-truncated/female-connector-truncated_collision_4.obj"/>
    <mesh file="./female-connector-truncated/female-connector-truncated/female-connector-truncated_collision_5.obj"/>
    <mesh file="./female-connector-truncated/female-connector-truncated/female-connector-truncated_collision_6.obj"/>
    <mesh file="./female-connector-truncated/female-connector-truncated/female-connector-truncated_collision_7.obj"/>
    <mesh file="./female-connector-truncated/female-connector-truncated/female-connector-truncated_collision_8.obj"/>
    <mesh file="./female-connector-truncated/female-connector-truncated/female-connector-truncated_collision_9.obj"/>
    <mesh file="./female-connector-truncated/female-connector-truncated/female-connector-truncated_collision_10.obj"/>
    <mesh file="./female-connector-truncated/female-connector-truncated/female-connector-truncated_collision_11.obj"/>
    <mesh file="./female-connector-truncated/female-connector-truncated/female-connector-truncated_collision_12.obj"/>
    <mesh file="./female-connector-truncated/female-connector-truncated/female-connector-truncated_collision_13.obj"/>
    <mesh file="./female-connector-truncated/female-connector-truncated/female-connector-truncated_collision_14.obj"/>
    <mesh file="./female-connector-truncated/female-connector-truncated/female-connector-truncated_collision_15.obj"/>
    <mesh file="./female-connector-truncated/female-connector-truncated/female-connector-truncated_collision_16.obj"/>
    <mesh file="./female-connector-truncated/female-connector-truncated/female-connector-truncated_collision_17.obj"/>
    <mesh file="./female-connector-truncated/female-connector-truncated/female-connector-truncated_collision_18.obj"/>
    <mesh file="./female-connector-truncated/female-connector-truncated/female-connector-truncated_collision_19.obj"/>
    <mesh file="./female-connector-truncated/female-connector-truncated/female-connector-truncated_collision_20.obj"/>
    <mesh file="./female-connector-truncated/female-connector-truncated/female-connector-truncated_collision_21.obj"/>
    <mesh file="./female-connector-truncated/female-connector-truncated/female-connector-truncated_collision_22.obj"/>
    <mesh file="./female-connector-truncated/female-connector-truncated/female-connector-truncated_collision_23.obj"/>
    <mesh file="./female-connector-truncated/female-connector-truncated/female-connector-truncated_collision_24.obj"/>
    <mesh file="./female-connector-truncated/female-connector-truncated/female-connector-truncated_collision_25.obj"/>
    <mesh file="./female-connector-truncated/female-connector-truncated/female-connector-truncated_collision_26.obj"/>
    <mesh file="./female-connector-truncated/female-connector-truncated/female-connector-truncated_collision_27.obj"/>
    <mesh file="./female-connector-truncated/female-connector-truncated/female-connector-truncated_collision_28.obj"/>
    <mesh file="./female-connector-truncated/female-connector-truncated/female-connector-truncated_collision_29.obj"/>
    <mesh file="./female-connector-truncated/female-connector-truncated/female-connector-truncated_collision_30.obj"/>
    <mesh file="./female-connector-truncated/female-connector-truncated/female-connector-truncated_collision_31.obj"/>
    <mesh file="./female-connector-truncated/female-connector-truncated/female-connector-truncated_collision_32.obj"/>
    <mesh file="./female-connector-truncated/female-connector-truncated/female-connector-truncated_collision_33.obj"/>
    <mesh file="./female-connector-truncated/female-connector-truncated/female-connector-truncated_collision_34.obj"/>
    <mesh file="./female-connector-truncated/female-connector-truncated/female-connector-truncated_collision_35.obj"/>
    <mesh file="./female-connector-truncated/female-connector-truncated/female-connector-truncated_collision_36.obj"/>
    <mesh file="./female-connector-truncated/female-connector-truncated/female-connector-truncated_collision_37.obj"/>
    <mesh file="./female-connector-truncated/female-connector-truncated/female-connector-truncated_collision_38.obj"/>
    <mesh file="./female-connector-truncated/female-connector-truncated/female-connector-truncated_collision_39.obj"/>
    <mesh file="./female-connector-truncated/female-connector-truncated/female-connector-truncated_collision_40.obj"/>
    <mesh file="./female-connector-truncated/female-connector-truncated/female-connector-truncated_collision_41.obj"/>
    <mesh file="./female-connector-truncated/female-connector-truncated/female-connector-truncated_collision_42.obj"/>
    <mesh file="./female-connector-truncated/female-connector-truncated/female-connector-truncated_collision_43.obj"/>
    <mesh file="./female-connector-truncated/female-connector-truncated/female-connector-truncated_collision_44.obj"/>
    <mesh file="./female-connector-truncated/female-connector-truncated/female-connector-truncated_collision_45.obj"/>
    <mesh file="./female-connector-truncated/female-connector-truncated/female-connector-truncated_collision_46.obj"/>
    <mesh file="./female-connector-truncated/female-connector-truncated/female-connector-truncated_collision_47.obj"/>
    <mesh file="./female-connector-truncated/female-connector-truncated/female-connector-truncated_collision_48.obj"/>
    <mesh file="./female-connector-truncated/female-connector-truncated/female-connector-truncated_collision_49.obj"/>
    <mesh file="./female-connector-truncated/female-connector-truncated/female-connector-truncated_collision_50.obj"/>
    <mesh file="./female-connector-truncated/female-connector-truncated/female-connector-truncated_collision_51.obj"/>
    <mesh file="./female-connector-truncated/female-connector-truncated/female-connector-truncated_collision_52.obj"/>
    <mesh file="./female-connector-truncated/female-connector-truncated/female-connector-truncated_collision_53.obj"/>
    <mesh file="./female-connector-truncated/female-connector-truncated/female-connector-truncated_collision_54.obj"/>
    <mesh file="./female-connector-truncated/female-connector-truncated/female-connector-truncated_collision_55.obj"/>
    <mesh file="./female-connector-truncated/female-connector-truncated/female-connector-truncated_collision_56.obj"/>
    <mesh file="./female-connector-truncated/female-connector-truncated/female-connector-truncated_collision_57.obj"/>
    <mesh file="./female-connector-truncated/female-connector-truncated/female-connector-truncated_collision_58.obj"/>
    <mesh file="./female-connector-truncated/female-connector-truncated/female-connector-truncated_collision_59.obj"/>
    <mesh file="./female-connector-truncated/female-connector-truncated/female-connector-truncated_collision_60.obj"/>
    <mesh file="./female-connector-truncated/female-connector-truncated/female-connector-truncated_collision_61.obj"/>
    <mesh file="./female-connector-truncated/female-connector-truncated/female-connector-truncated_collision_62.obj"/>
    <mesh file="./female-connector-truncated/female-connector-truncated/female-connector-truncated_collision_63.obj"/>
    <mesh file="./female-connector-truncated/female-connector-truncated/female-connector-truncated_collision_64.obj"/>
    <mesh file="./female-connector-truncated/female-connector-truncated/female-connector-truncated_collision_65.obj"/>
    <mesh file="./female-connector-truncated/female-connector-truncated/female-connector-truncated_collision_66.obj"/>

    <texture name="tex_ground" type="2d" builtin="checker" width="512" height="512" />
    <material name="groundplane" texture="tex_ground" texrepeat="5 5" reflectance="0.2" />
  </asset>

  <worldbody>
    <geom name="hull" type="mesh" rgba="0.7 0.7 0.7 1" mesh="link0"/>
    <body name="link1" pos="0 0 0.155" quat="0 0 0 -1">
      <inertial pos="0 0.01 0.15" mass="3.7" diaginertia="0.03 0.03 0.01"/>
      <joint name="joint1" pos="0 0 0" axis="0 0 1" actuatorfrcrange="-123 123"/>
      <geom type="mesh" rgba="1 1 1 1" mesh="link1"/>
      <body name="link2" pos="0 0.03 0.21">
        <inertial pos="0 0.04 0.1" mass="2.7" diaginertia="0.02 0.02 0.01"/>
        <joint name="joint2" pos="0 0 0" axis="0 1 0" actuatorfrcrange="-123 123"/>
        <geom type="mesh" rgba="1 1 1 1" mesh="link2"/>
        <body name="link3" pos="0 0.035 0.205">
          <inertial pos="-0.01 0 0.13" mass="2.4" diaginertia="0.01 0.01 0.01"/>
          <joint name="joint3" pos="0 0 0" axis="0 0 1" actuatorfrcrange="-64 64"/>
          <geom type="mesh" rgba="1 1 1 1" mesh="link3"/>
          <body name="link4" pos="-0.02 -0.03 0.19" quat="0 0 0 -1">
            <inertial pos="-0.01 0.03 0.1" mass="2.4" diaginertia="0.02 0.02 0.01"/>
            <joint name="joint4" pos="0 0 0" axis="0 1 0" actuatorfrcrange="-64 64"/>
            <geom type="mesh" rgba="1 1 1 1" mesh="link4"/>
            <body name="link5" pos="-0.02 0.025 0.195" quat="0 0 0 -1">
              <inertial pos="0 0 0.13" mass="2.4" diaginertia="0.01 0.01 0.01"/>
              <joint name="joint5" pos="0 0 0" axis="0 0 1" actuatorfrcrange="-39 39"/>
              <geom type="mesh" rgba="1 1 1 1" mesh="link5"/>
              <body name="link6" pos="0 0.03 0.19">
                <inertial pos="0.02 0.06 0.07" mass="2.2" diaginertia="0.01 0.01 0.01"/>
                <joint name="joint6" pos="0 0 0" axis="0 1 0" actuatorfrcrange="-39 39"/>
                <geom type="mesh" rgba="1 1 1 1" mesh="link6"/>
                <body name="link7" pos="-0.015 0.073 0.11" quat="0.707107 0 -0.707107 0">
                <site name="force_site" pos="0 0 0"/>
                  <inertial pos="0 0 0.05" mass="1.4" diaginertia="0.1 0.1 0.1"/>
                  <joint name="joint7" pos="0 0 0" axis="0 0 1" actuatorfrcrange="-39 39"/>
                  <geom type="mesh" rgba="1 1 1 1" mesh="link7"/>
                    <!-- Add the point mass here -->
                  <body name="point_mass_body" pos="0 0 0.15">
                    <inertial pos="0 0 0" mass="0.893" diaginertia="0.0001 0.0001 0.0001"/>

                    <geom name="point_mass_cylinder" type="cylinder"
                        size="0.01 0.2"  
                        rgba="1 0 0 1"     
                        contype="0" conaffinity="0"  
                        group="2"/>       

                    <body name="male-connector-minimal" pos="0 -0.005 0.21" quat="0.707 -0.707 0 0">
                        <geom material="0.596078_0.666667_0.686275_0.000000_0.000000" mesh="male-connector-minimal" class="visual"/>
                        <geom mesh="male-connector-minimal_collision_0" rgba="0.7990343555764012 0.01337688592684616 0.7684348975923024 1" class="collision"/>
                        <geom mesh="male-connector-minimal_collision_1" rgba="0.9716724395095205 0.4155773668635704 0.4891406227984333 1" class="collision"/>
                        <geom mesh="male-connector-minimal_collision_2" rgba="0.14830229256383265 0.6475927777174105 0.7338673709396254 1" class="collision"/>
                        <geom mesh="male-connector-minimal_collision_3" rgba="0.9669567561504457 0.1597578128209678 0.014474842421785983 1" class="collision"/>
                        <geom mesh="male-connector-minimal_collision_4" rgba="0.6799236025959631 0.3699565607110832 0.5072143585472161 1" class="collision"/>
                        <geom mesh="male-connector-minimal_collision_5" rgba="0.4268029638925618 0.48928493834570574 0.5899333271522715 1" class="collision"/>
                        <geom mesh="male-connector-minimal_collision_6" rgba="0.8260291399072678 0.4209205902022757 0.8043892236206673 1" class="collision"/>
                        <geom mesh="male-connector-minimal_collision_7" rgba="0.6130379479462504 0.42045031701196356 0.540917958831619 1" class="collision"/>
                    </body>
                  </body>
                </body>
              </body>
            </body>
          </body>
        </body>
      </body>
    </body>

    <light pos="0 0 1.5" dir="0 0 -1" directional="true" />
    <geom name="floor" size="0 0 0.05" pos="0 0 0" type="plane" material="groundplane" friction="1 0.005 0.0001" />

    <body name="female-connector-truncated" pos="0 0.4 0.03" quat="0 0 0 1">
        <geom material="0.498039_0.498039_0.498039_0.000000_0.000000" mesh="female-connector-truncated" class="visual"/>
        <geom mesh="female-connector-truncated_collision_0" rgba="0.24406023908045216 0.2882725435425405 0.24224156632472527 1" class="collision"/>
        <geom mesh="female-connector-truncated_collision_1" rgba="0.5139487061153281 0.6449378782206079 0.7326927404805909 1" class="collision"/>
        <geom mesh="female-connector-truncated_collision_2" rgba="0.750323466443435 0.6407352643844305 0.7877987007963392 1" class="collision"/>
        <geom mesh="female-connector-truncated_collision_3" rgba="0.8294793595999292 0.2868047267574202 0.21338557150418702 1" class="collision"/>
        <geom mesh="female-connector-truncated_collision_4" rgba="0.9506013111127717 0.18641228312960811 0.5232678850944085 1" class="collision"/>
        <geom mesh="female-connector-truncated_collision_5" rgba="0.30052388190553125 0.8150597267178903 0.9557183231058312 1" class="collision"/>
        <geom mesh="female-connector-truncated_collision_6" rgba="0.7405526819576826 0.6052022450929406 0.46917873979622127 1" class="collision"/>
        <geom mesh="female-connector-truncated_collision_7" rgba="0.5352762047155858 0.541400759222529 0.9357359400206434 1" class="collision"/>
        <geom mesh="female-connector-truncated_collision_8" rgba="0.3289215167588494 0.9817921089340991 0.6278944385477104 1" class="collision"/>
        <geom mesh="female-connector-truncated_collision_9" rgba="0.18501461952582365 0.5436535144650609 0.3371179372419627 1" class="collision"/>
        <geom mesh="female-connector-truncated_collision_10" rgba="0.973746818480118 0.883583734306336 0.9762622045417593 1" class="collision"/>
        <geom mesh="female-connector-truncated_collision_11" rgba="0.7340442355371637 0.03156187101740804 0.10716007011344297 1" class="collision"/>
        <geom mesh="female-connector-truncated_collision_12" rgba="0.551861793737998 0.018333188909415155 0.5569363440042928 1" class="collision"/>
        <geom mesh="female-connector-truncated_collision_13" rgba="0.40837618639639695 0.2759759188679788 0.14892411219435386 1" class="collision"/>
        <geom mesh="female-connector-truncated_collision_14" rgba="0.9823758494522707 0.12400832653045135 0.16722408432032143 1" class="collision"/>
        <geom mesh="female-connector-truncated_collision_15" rgba="0.15826707813569474 0.6873855610554702 0.3611356853240594 1" class="collision"/>
        <geom mesh="female-connector-truncated_collision_16" rgba="0.4801392098082624 0.43085385886875016 0.23398024339737744 1" class="collision"/>
        <geom mesh="female-connector-truncated_collision_17" rgba="0.7649883400622757 0.793766084878964 0.23748596214331297 1" class="collision"/>
        <geom mesh="female-connector-truncated_collision_18" rgba="0.5043707504382862 0.48749079039615284 0.4167157342432458 1" class="collision"/>
        <geom mesh="female-connector-truncated_collision_19" rgba="0.8285354283075188 0.6983770539272974 0.9806030421113423 1" class="collision"/>
        <geom mesh="female-connector-truncated_collision_20" rgba="0.5727106659696336 0.08004079596036129 0.6883889809072945 1" class="collision"/>
        <geom mesh="female-connector-truncated_collision_21" rgba="0.26954976810644726 0.5416288761429333 0.9978608346088038 1" class="collision"/>
        <geom mesh="female-connector-truncated_collision_22" rgba="0.7937595566128488 0.12908033551308296 0.8901840237900103 1" class="collision"/>
        <geom mesh="female-connector-truncated_collision_23" rgba="0.11147447083099882 0.8596014139945233 0.9281744105091719 1" class="collision"/>
        <geom mesh="female-connector-truncated_collision_24" rgba="0.7186271014459746 0.5985949551900469 0.9144664790288777 1" class="collision"/>
        <geom mesh="female-connector-truncated_collision_25" rgba="0.709671058141099 0.4391316366777226 0.5954093251198409 1" class="collision"/>
        <geom mesh="female-connector-truncated_collision_26" rgba="0.5305911141726788 0.11085976710516265 0.17389604290254457 1" class="collision"/>
        <geom mesh="female-connector-truncated_collision_27" rgba="0.062469433282581366 0.201632263228399 0.5513279987231168 1" class="collision"/>
        <geom mesh="female-connector-truncated_collision_28" rgba="0.5800300503228571 0.17302899578711695 0.8655160751980404 1" class="collision"/>
        <geom mesh="female-connector-truncated_collision_29" rgba="0.684816367194578 0.22406466750313492 0.4824408068092161 1" class="collision"/>
        <geom mesh="female-connector-truncated_collision_30" rgba="0.6400884257631363 0.09342386521108748 0.24594116239949515 1" class="collision"/>
        <geom mesh="female-connector-truncated_collision_31" rgba="0.1923411427851186 0.5525503419689786 0.30326832567207795 1" class="collision"/>
        <geom mesh="female-connector-truncated_collision_32" rgba="0.2140916235920044 0.09471958355997634 0.27187062329551837 1" class="collision"/>
        <geom mesh="female-connector-truncated_collision_33" rgba="0.8241795367962611 0.4379151754277173 0.20276089102013284 1" class="collision"/>
        <geom mesh="female-connector-truncated_collision_34" rgba="0.21948939835320258 0.81441565914042 0.2043165457888797 1" class="collision"/>
        <geom mesh="female-connector-truncated_collision_35" rgba="0.8552053523565558 0.5412642083558915 0.9272629386547079 1" class="collision"/>
        <geom mesh="female-connector-truncated_collision_36" rgba="0.7441193573578497 0.5925317750581905 0.9518737585427347 1" class="collision"/>
        <geom mesh="female-connector-truncated_collision_37" rgba="0.6321921407585437 0.49971559409933664 0.4658336499757534 1" class="collision"/>
        <geom mesh="female-connector-truncated_collision_38" rgba="0.41005242453726565 0.7948755513258421 0.882422018686714 1" class="collision"/>
        <geom mesh="female-connector-truncated_collision_39" rgba="0.008352687678277237 0.011453246809263185 0.3010710984110998 1" class="collision"/>
        <geom mesh="female-connector-truncated_collision_40" rgba="0.8823876924142402 0.6249944569206294 0.45957241483580635 1" class="collision"/>
        <geom mesh="female-connector-truncated_collision_41" rgba="0.2468525466930116 0.37330471458058334 0.655637677878652 1" class="collision"/>
        <geom mesh="female-connector-truncated_collision_42" rgba="0.6405013252332036 0.10094393747183428 0.4331624481131765 1" class="collision"/>
        <geom mesh="female-connector-truncated_collision_43" rgba="0.12148184351521951 0.6744830119515657 0.7852318839609512 1" class="collision"/>
        <geom mesh="female-connector-truncated_collision_44" rgba="0.6197046098707124 0.5353558572248629 0.08261885957321236 1" class="collision"/>
        <geom mesh="female-connector-truncated_collision_45" rgba="0.3146203047544809 0.7428533732743118 0.7545683572419407 1" class="collision"/>
        <geom mesh="female-connector-truncated_collision_46" rgba="0.30413823387798045 0.16820457436251168 0.3270785536627959 1" class="collision"/>
        <geom mesh="female-connector-truncated_collision_47" rgba="0.014217456071223267 0.8365278984676519 0.09983453003001741 1" class="collision"/>
        <geom mesh="female-connector-truncated_collision_48" rgba="0.5491605180411548 0.9679100693090362 0.6014057374552891 1" class="collision"/>
        <geom mesh="female-connector-truncated_collision_49" rgba="0.45608189242155484 0.13583017761428162 0.9403184937638935 1" class="collision"/>
        <geom mesh="female-connector-truncated_collision_50" rgba="0.39363799933861565 0.41824689892678757 0.8609975188165978 1" class="collision"/>
        <geom mesh="female-connector-truncated_collision_51" rgba="0.16321411924821572 0.5935605380418147 0.09349288767456054 1" class="collision"/>
        <geom mesh="female-connector-truncated_collision_52" rgba="0.30089868098285877 0.9366256197107664 0.8696927453601121 1" class="collision"/>
        <geom mesh="female-connector-truncated_collision_53" rgba="0.7308336144470154 0.13177487328380966 0.7844838485960907 1" class="collision"/>
        <geom mesh="female-connector-truncated_collision_54" rgba="0.8270374195642552 0.32009797946164753 0.08376413431531526 1" class="collision"/>
        <geom mesh="female-connector-truncated_collision_55" rgba="0.7724191492376846 0.5771525974300367 0.23720941734345424 1" class="collision"/>
        <geom mesh="female-connector-truncated_collision_56" rgba="0.054793158943063136 0.18091656800715972 0.9947281501841678 1" class="collision"/>
        <geom mesh="female-connector-truncated_collision_57" rgba="0.5448199449551653 0.31756087933805943 0.6964147692415421 1" class="collision"/>
        <geom mesh="female-connector-truncated_collision_58" rgba="0.004151922750349146 0.8034378928329832 0.8283639286215482 1" class="collision"/>
        <geom mesh="female-connector-truncated_collision_59" rgba="0.32680259954732516 0.08574464607557708 0.8869934955870339 1" class="collision"/>
        <geom mesh="female-connector-truncated_collision_60" rgba="0.7724623270887944 0.1384440074054345 0.6548756540778083 1" class="collision"/>
        <geom mesh="female-connector-truncated_collision_61" rgba="0.09779636005916736 0.551246937303388 0.3569475893047893 1" class="collision"/>
        <geom mesh="female-connector-truncated_collision_62" rgba="0.008347453514204295 0.4352421392680713 0.7522002986981471 1" class="collision"/>
        <geom mesh="female-connector-truncated_collision_63" rgba="0.43697494252714375 0.5247014227383905 0.15779865772695534 1" class="collision"/>
        <geom mesh="female-connector-truncated_collision_64" rgba="0.6067092223120281 0.3964589866156981 0.37121954130840684 1" class="collision"/>
        <geom mesh="female-connector-truncated_collision_65" rgba="0.44990256542995744 0.9807156881446643 0.3251814937936609 1" class="collision"/>
        <geom mesh="female-connector-truncated_collision_66" rgba="0.4862699189558579 0.15440728675981452 0.9909902892642146 1" class="collision"/>
    </body>

  </worldbody>

  <actuator>
    <motor class="rizon4s" name="joint1" joint="joint1" ctrlrange="-87 87"/>
    <motor class="rizon4s" name="joint2" joint="joint2" ctrlrange="-87 87"/>
    <motor class="rizon4s" name="joint3" joint="joint3" ctrlrange="-87 87"/>
    <motor class="rizon4s" name="joint4" joint="joint4" ctrlrange="-87 87"/>
    <motor class="rizon4s" name="joint5" joint="joint5" ctrlrange="-12 12"/>
    <motor class="rizon4s" name="joint6" joint="joint6" ctrlrange="-12 12"/>
    <motor class="rizon4s" name="joint7" joint="joint7" ctrlrange="-12 12"/>
  </actuator>

  <sensor>
    <force name="force_sensor" site="force_site"/>
    <torque name="torque_sensor" site="force_site"/>
  </sensor>

  

  <keyframe>
    <key name="home" qpos="0 0 0 -1.57079 0 1.57079 -0.7853" ctrl="0 0 0 -1.57079 0 1.57079 -0.7853"/>
  </keyframe>

</mujoco>
