<mujoco model="rizon4s">
  <compiler angle="radian"/>

  <option integrator="implicitfast"/>

  <default>
    <default class="rizon4s">
      <joint armature="0.1" damping="1"/>
      <position inheritrange="1"/>
      <default class="visual">
        <geom type="mesh" group="2" contype="0" conaffinity="0"/>
      </default>
      <default class="collision">
        <geom type="mesh" group="3" mass="0" density="0"/>
      </default>
      <site size="0.001" rgba="0.5 0.5 0.5 0.3" group="4"/>
    </default>
  </default>

  <asset>
    <mesh name="link0" file="link0.stl"/>
    <mesh name="link1" file="link1.stl"/>
    <mesh name="link2" file="link2.stl"/>
    <mesh name="link3" file="link3.stl"/>
    <mesh name="link4" file="link4.stl"/>
    <mesh name="link5" file="link5.stl"/>
    <mesh name="link6" file="link6.stl"/>
    <mesh name="link7" file="link7.stl"/>
  </asset>

  <worldbody>
    <geom name="hull" type="mesh" rgba="0.7 0.7 0.7 1" mesh="link0"/>
    <body name="link1" pos="0 0 0.155" quat="0 0 0 -1">
      <inertial pos="0 0.01 0.15" mass="3.7" diaginertia="0.03 0.03 0.01"/>
      <joint name="joint1" pos="0 0 0" axis="0 0 1" range="-2.7925 2.7925" actuatorfrcrange="-123 123"/>
      <geom type="mesh" rgba="1 1 1 1" mesh="link1"/>
      <body name="link2" pos="0 0.03 0.21">
        <inertial pos="0 0.04 0.1" mass="2.7" diaginertia="0.02 0.02 0.01"/>
        <joint name="joint2" pos="0 0 0" axis="0 1 0" range="-2.2689 2.2689" actuatorfrcrange="-123 123"/>
        <geom type="mesh" rgba="1 1 1 1" mesh="link2"/>
        <body name="link3" pos="0 0.035 0.205">
          <inertial pos="-0.01 0 0.13" mass="2.4" diaginertia="0.01 0.01 0.01"/>
          <joint name="joint3" pos="0 0 0" axis="0 0 1" range="-2.9671 2.9671" actuatorfrcrange="-64 64"/>
          <geom type="mesh" rgba="1 1 1 1" mesh="link3"/>
          <body name="link4" pos="-0.02 -0.03 0.19" quat="0 0 0 -1">
            <inertial pos="-0.01 0.03 0.1" mass="2.4" diaginertia="0.02 0.02 0.01"/>
            <joint name="joint4" pos="0 0 0" axis="0 1 0" range="-1.8675 2.6878" actuatorfrcrange="-64 64"/>
            <geom type="mesh" rgba="1 1 1 1" mesh="link4"/>
            <body name="link5" pos="-0.02 0.025 0.195" quat="0 0 0 -1">
              <inertial pos="0 0 0.13" mass="2.4" diaginertia="0.01 0.01 0.01"/>
              <joint name="joint5" pos="0 0 0" axis="0 0 1" range="-2.9671 2.9671" actuatorfrcrange="-39 39"/>
              <geom type="mesh" rgba="1 1 1 1" mesh="link5"/>
              <body name="link6" pos="0 0.03 0.19">
                <inertial pos="0.02 0.06 0.07" mass="2.2" diaginertia="0.01 0.01 0.01"/>
                <joint name="joint6" pos="0 0 0" axis="0 1 0" range="-1.3963 4.5379" actuatorfrcrange="-39 39"/>
                <geom type="mesh" rgba="1 1 1 1" mesh="link6"/>
                <body name="link7" pos="-0.015 0.073 0.11" quat="0.707107 0 -0.707107 0">
                  <inertial pos="0 0 0.05" mass="1.4" diaginertia="0.1 0.1 0.1"/>
                  <joint name="joint7" pos="0 0 0" axis="0 0 1" range="-2.9671 2.9671" actuatorfrcrange="-39 39"/>
                  <geom type="mesh" rgba="1 1 1 1" mesh="link7"/>
                </body>
              </body>
            </body>
          </body>
        </body>
      </body>
    </body>
  </worldbody>

  <actuator>
    <motor class="rizon4s" name="joint1" joint="joint1" ctrlrange="-87 87"/>
    <motor class="rizon4s" name="joint2" joint="joint2" ctrlrange="-87 87"/>
    <motor class="rizon4s" name="joint3" joint="joint3" ctrlrange="-87 87"/>
    <motor class="rizon4s" name="joint4" joint="joint4" ctrlrange="-87 87"/>
    <motor class="rizon4s" name="joint5" joint="joint5" ctrlrange="-12 12"/>
    <motor class="rizon4s" name="joint6" joint="joint6" ctrlrange="-12 12"/>
    <motor class="rizon4s" name="joint7" joint="joint7" ctrlrange="-12 12"/>
  </actuator>

  <keyframe>
    <key name="home" qpos="0 0 0 -1.57079 0 1.57079 -0.7853" ctrl="0 0 0 -1.57079 0 1.57079 -0.7853"/>
  </keyframe>

</mujoco>
